Unhandled exception on new_message_handler
Traceback (most recent call last):
  File "/opt/homebrew/lib/python3.11/site-packages/telethon/client/updates.py", line 570, in _dispatch_update
    await callback(event)
  File "/Users/nicolas/TelegramBots/LastStage/src/main.py", line 92, in new_message_handler
    await group.new_message_handler(event, promptC, promptA, model, temperature, max_tokens, request_timeout, collection_messages)
  File "/Users/nicolas/TelegramBots/LastStage/src/class_group.py", line 20, in new_message_handler
    await message.calc_score(prompt_c, model, temperature, max_tokens, request_timeout, collection_messages, self)
  File "/Users/nicolas/TelegramBots/LastStage/src/class_message.py", line 24, in calc_score
    print(prompt_c.to_string(self, collection_messages))
          ^^^^^^^^^^^^^^^^^^^^^^^^^^^^^^^^^^^^^^^^^^^^^
  File "/Users/nicolas/TelegramBots/LastStage/src/classes_prompts.py", line 37, in to_string
    return string + self.examples(collection_messages)
                    ^^^^^^^^^^^^^^^^^^^^^^^^^^^^^^^^^^
  File "/Users/nicolas/TelegramBots/LastStage/src/classes_prompts.py", line 20, in examples
    if examples_cursor.count() == 0:
       ^^^^^^^^^^^^^^^^^^^^^
AttributeError: 'Cursor' object has no attribute 'count'
model           = gpt-3.5-turbo
temperature     = 0.0
max_len_message = 600
channels        = [-1001842901217, -1001905441409, -1001863996867, -1001944316671, -1001919265899]

