Unhandled exception on new_message_handler
Traceback (most recent call last):
  File "/home/an/.local/lib/python3.8/site-packages/urllib3/connectionpool.py", line 536, in _make_request
    response = conn.getresponse()
  File "/home/an/.local/lib/python3.8/site-packages/urllib3/connection.py", line 461, in getresponse
    httplib_response = super().getresponse()
  File "/usr/lib/python3.8/http/client.py", line 1348, in getresponse
    response.begin()
  File "/usr/lib/python3.8/http/client.py", line 316, in begin
    version, status, reason = self._read_status()
  File "/usr/lib/python3.8/http/client.py", line 277, in _read_status
    line = str(self.fp.readline(_MAXLINE + 1), "iso-8859-1")
  File "/usr/lib/python3.8/socket.py", line 669, in readinto
    return self._sock.recv_into(b)
  File "/usr/lib/python3.8/ssl.py", line 1241, in recv_into
    return self.read(nbytes, buffer)
  File "/usr/lib/python3.8/ssl.py", line 1099, in read
    return self._sslobj.read(len, buffer)
socket.timeout: The read operation timed out

The above exception was the direct cause of the following exception:

Traceback (most recent call last):
  File "/home/an/.local/lib/python3.8/site-packages/requests/adapters.py", line 486, in send
    resp = conn.urlopen(
  File "/home/an/.local/lib/python3.8/site-packages/urllib3/connectionpool.py", line 844, in urlopen
    retries = retries.increment(
  File "/home/an/.local/lib/python3.8/site-packages/urllib3/util/retry.py", line 470, in increment
    raise reraise(type(error), error, _stacktrace)
  File "/home/an/.local/lib/python3.8/site-packages/urllib3/util/util.py", line 39, in reraise
    raise value
  File "/home/an/.local/lib/python3.8/site-packages/urllib3/connectionpool.py", line 790, in urlopen
    response = self._make_request(
  File "/home/an/.local/lib/python3.8/site-packages/urllib3/connectionpool.py", line 538, in _make_request
    self._raise_timeout(err=e, url=url, timeout_value=read_timeout)
  File "/home/an/.local/lib/python3.8/site-packages/urllib3/connectionpool.py", line 370, in _raise_timeout
    raise ReadTimeoutError(
urllib3.exceptions.ReadTimeoutError: HTTPSConnectionPool(host='api.openai.com', port=443): Read timed out. (read timeout=10)

During handling of the above exception, another exception occurred:

Traceback (most recent call last):
  File "/home/an/.local/lib/python3.8/site-packages/openai/api_requestor.py", line 516, in request_raw
    result = _thread_context.session.request(
  File "/home/an/.local/lib/python3.8/site-packages/requests/sessions.py", line 589, in request
    resp = self.send(prep, **send_kwargs)
  File "/home/an/.local/lib/python3.8/site-packages/requests/sessions.py", line 703, in send
    r = adapter.send(request, **kwargs)
  File "/home/an/.local/lib/python3.8/site-packages/requests/adapters.py", line 532, in send
    raise ReadTimeout(e, request=request)
requests.exceptions.ReadTimeout: HTTPSConnectionPool(host='api.openai.com', port=443): Read timed out. (read timeout=10)

The above exception was the direct cause of the following exception:

Traceback (most recent call last):
  File "/home/an/.local/lib/python3.8/site-packages/telethon/client/updates.py", line 520, in _dispatch_update
    await callback(event)
  File "main.py", line 92, in new_message_handler
    await group.new_message_handler(event, promptC, promptA, model, temperature, max_tokens, request_timeout, collection_messages)
  File "/mnt/md0/travail hobby/2022 2023 stage/github 7/src/class_group.py", line 21, in new_message_handler
    await message.calc_affirmations(prompt_a, model, temperature, max_tokens, request_timeout, collection_messages, self)
  File "/mnt/md0/travail hobby/2022 2023 stage/github 7/src/class_message.py", line 41, in calc_affirmations
    response = openai.ChatCompletion.create( # await ?
  File "/home/an/.local/lib/python3.8/site-packages/openai/api_resources/chat_completion.py", line 25, in create
    return super().create(*args, **kwargs)
  File "/home/an/.local/lib/python3.8/site-packages/openai/api_resources/abstract/engine_api_resource.py", line 153, in create
    response, _, api_key = requestor.request(
  File "/home/an/.local/lib/python3.8/site-packages/openai/api_requestor.py", line 216, in request
    result = self.request_raw(
  File "/home/an/.local/lib/python3.8/site-packages/openai/api_requestor.py", line 527, in request_raw
    raise error.Timeout("Request timed out: {}".format(e)) from e
openai.error.Timeout: Request timed out: HTTPSConnectionPool(host='api.openai.com', port=443): Read timed out. (read timeout=10)
model           = gpt-3.5-turbo
temperature     = 0.0
max_len_message = 600
channels        = [-1001842901217, -1001905441409, -1001863996867, -1001944316671, -1001919265899]

0  positive author attitude
1  the message is advantageous for the actual political power
2  exaggerations
3  lack of object concordance
4  appeal to the intellect
5  appeal to emotions
6  appeal to virtues
7  appeal to ethics
8  appeal to blinding generalities as fatherland, peace, glory, justice, honor
9  appeal to fear
10 appeal to the threat from other countries
11 appeal to hatred
12 appeal to authority
13 appeal to human rights
14 criticism of the actual political power
15 generalizations
16 seemingly scientific appearance, but only seemingly
17 real scientific proofs of the information
18 real proofs of the information
19 euphemismes replacing offensive expressions
20 euphemismes replacing war or victims
21 formal register of the texte
22 eupbeneficiaries of the information regarding to politics
23 flattery to the reader
24 dilemma between only two possibilities
25 criticisme of a person instead of criticism of his arguments
26 underestimation of the proofs of the opponents

calc_affirmations
