Unhandled exception on new_message_handler
Traceback (most recent call last):
  File "/opt/homebrew/lib/python3.11/site-packages/telethon/client/updates.py", line 570, in _dispatch_update
    await callback(event)
  File "/Users/nicolas/TelegramBots/LastStage/src/main.py", line 92, in new_message_handler
    await group.new_message_handler(event, promptC, promptA, model, temperature, max_tokens, request_timeout, collection_messages)
  File "/Users/nicolas/TelegramBots/LastStage/src/class_group.py", line 20, in new_message_handler
    await message.calc_score(prompt_c, model, temperature, max_tokens, request_timeout, collection_messages, self)
  File "/Users/nicolas/TelegramBots/LastStage/src/class_message.py", line 27, in calc_score
    response = openai.ChatCompletion.create( # object OpenAIObject can't be used in 'await'  ???
               ^^^^^^^^^^^^^^^^^^^^^^^^^^^^^^^^^^^^^^^^^^^^^^^^^^^^^^^^^^^^^^^^^^^^^^^^^^^^^^^^^
  File "/opt/homebrew/lib/python3.11/site-packages/openai/api_resources/chat_completion.py", line 25, in create
    return super().create(*args, **kwargs)
           ^^^^^^^^^^^^^^^^^^^^^^^^^^^^^^^
  File "/opt/homebrew/lib/python3.11/site-packages/openai/api_resources/abstract/engine_api_resource.py", line 153, in create
    response, _, api_key = requestor.request(
                           ^^^^^^^^^^^^^^^^^^
  File "/opt/homebrew/lib/python3.11/site-packages/openai/api_requestor.py", line 288, in request
    result = self.request_raw(
             ^^^^^^^^^^^^^^^^^
  File "/opt/homebrew/lib/python3.11/site-packages/openai/api_requestor.py", line 581, in request_raw
    abs_url, headers, data = self._prepare_request_raw(
                             ^^^^^^^^^^^^^^^^^^^^^^^^^^
  File "/opt/homebrew/lib/python3.11/site-packages/openai/api_requestor.py", line 553, in _prepare_request_raw
    data = json.dumps(params).encode()
           ^^^^^^^^^^^^^^^^^^
  File "/opt/homebrew/Cellar/python@3.11/3.11.5/Frameworks/Python.framework/Versions/3.11/lib/python3.11/json/__init__.py", line 231, in dumps
    return _default_encoder.encode(obj)
           ^^^^^^^^^^^^^^^^^^^^^^^^^^^^
  File "/opt/homebrew/Cellar/python@3.11/3.11.5/Frameworks/Python.framework/Versions/3.11/lib/python3.11/json/encoder.py", line 200, in encode
    chunks = self.iterencode(o, _one_shot=True)
             ^^^^^^^^^^^^^^^^^^^^^^^^^^^^^^^^^^
  File "/opt/homebrew/Cellar/python@3.11/3.11.5/Frameworks/Python.framework/Versions/3.11/lib/python3.11/json/encoder.py", line 258, in iterencode
    return _iterencode(o, 0)
           ^^^^^^^^^^^^^^^^^
  File "/opt/homebrew/Cellar/python@3.11/3.11.5/Frameworks/Python.framework/Versions/3.11/lib/python3.11/json/encoder.py", line 180, in default
    raise TypeError(f'Object of type {o.__class__.__name__} '
TypeError: Object of type TypeError is not JSON serializable
model           = gpt-3.5-turbo
temperature     = 0.0
max_len_message = 600
channels        = [-1001842901217, -1001905441409, -1001863996867, -1001944316671, -1001919265899]

start calulating score
object of type 'Cursor' has no len()
