Unhandled exception on new_message_handler
Traceback (most recent call last):
  File "/opt/homebrew/lib/python3.11/site-packages/telethon/client/updates.py", line 570, in _dispatch_update
    await callback(event)
  File "/Users/nicolas/TelegramBots/LastStage/src/main.py", line 101, in new_message_handler
    await group.new_message_handler(event, promptC, promptA, model, temperature, max_tokens, request_timeout, collection_messages, collection_channels, collection_relations)
  File "/Users/nicolas/TelegramBots/LastStage/src/class_group.py", line 22, in new_message_handler
    await message.put_to_mongo(prompt_c, prompt_a, collection_messages, collection_channels, collection_relations)
  File "/Users/nicolas/TelegramBots/LastStage/src/class_message.py", line 129, in put_to_mongo
    score = compare_affirmations(self.affirmations, old_message)
            ^^^^^^^^^^^^^^^^^^^^^^^^^^^^^^^^^^^^^^^^^^^^^^^^^^^^
  File "/Users/nicolas/TelegramBots/LastStage/src/class_message.py", line 74, in compare_affirmations
    for affirmation, truth_value in new_affirmations.items():
                                    ^^^^^^^^^^^^^^^^^^^^^^
AttributeError: 'str' object has no attribute 'items'
model           = gpt-4
temperature     = 0.2
max_len_message = 600

[-1001842901217.0, -1001905441409.0, -1001863996867.0, -1001944316671.0, -1001919265899.0]
Updated average score for channel -1001905441409 to 0.0
Put to mongo successful.
<class 'str'> <class 'dict'>
{
    'The Kremlin has promised that Putin\'s performance at "Valdai" will be a global event': True
}
