Unhandled exception on new_message_handler
Traceback (most recent call last):
  File "/opt/homebrew/lib/python3.11/site-packages/telethon/client/updates.py", line 570, in _dispatch_update
    await callback(event)
  File "/Users/nicolas/TelegramBots/LastStage/src/main.py", line 100, in new_message_handler
    await group.new_message_handler(event, promptC, promptA, model, temperature, max_tokens, request_timeout, collection_messages)
  File "/Users/nicolas/TelegramBots/LastStage/src/class_group.py", line 22, in new_message_handler
    await message.put_to_mongo(prompt_c, prompt_a, collection_messages)
  File "/Users/nicolas/TelegramBots/LastStage/src/class_message.py", line 86, in put_to_mongo
    "affirmations": ast.literal_eval(self.affirmations),
                    ^^^^^^^^^^^^^^^^^^^^^^^^^^^^^^^^^^^
  File "/opt/homebrew/Cellar/python@3.11/3.11.5/Frameworks/Python.framework/Versions/3.11/lib/python3.11/ast.py", line 110, in literal_eval
    return _convert(node_or_string)
           ^^^^^^^^^^^^^^^^^^^^^^^^
  File "/opt/homebrew/Cellar/python@3.11/3.11.5/Frameworks/Python.framework/Versions/3.11/lib/python3.11/ast.py", line 109, in _convert
    return _convert_signed_num(node)
           ^^^^^^^^^^^^^^^^^^^^^^^^^
  File "/opt/homebrew/Cellar/python@3.11/3.11.5/Frameworks/Python.framework/Versions/3.11/lib/python3.11/ast.py", line 83, in _convert_signed_num
    return _convert_num(node)
           ^^^^^^^^^^^^^^^^^^
  File "/opt/homebrew/Cellar/python@3.11/3.11.5/Frameworks/Python.framework/Versions/3.11/lib/python3.11/ast.py", line 74, in _convert_num
    _raise_malformed_node(node)
  File "/opt/homebrew/Cellar/python@3.11/3.11.5/Frameworks/Python.framework/Versions/3.11/lib/python3.11/ast.py", line 71, in _raise_malformed_node
    raise ValueError(msg + f': {node!r}')
ValueError: malformed node or string: []
model           = gpt-4
temperature     = 0.2
max_len_message = 600

[-1001842901217.0, -1001905441409.0, -1001863996867.0, -1001944316671.0, -1001919265899.0]
Message(ID: 109, Text: В Кремле пообещали, что выступление Путина на «Валдае» станет** событием мирового масштаба**, Timestamp: 2023-10-06 05:23:57+00:00, Channel: -1001905441409)
some mistake
None
[-1001842901217.0, -1001905441409.0, -1001863996867.0, -1001944316671.0, -1001919265899.0]
[-1001842901217.0, -1001905441409.0, -1001863996867.0, -1001944316671.0, -1001919265899.0]
[-1001842901217.0, -1001905441409.0, -1001863996867.0, -1001944316671.0, -1001919265899.0]
[-1001842901217.0, -1001905441409.0, -1001863996867.0, -1001944316671.0, -1001919265899.0]
